Workbook

Sheet Training Log
A1: Abbas Alhimed · Running Training Log
A2: 8-week training block · February 1 – March 31, 2026 · Built in Excel with live formulas
A4: Date | B4: Day | C4: Week # | D4: Run Type | E4: Distance (mi) | F4: Pace (min/mi) | G4: Duration (min) | H4: HR (bpm) | I4: Calories | J4: Weather | K4: Notes
A5: 46054 | B5: Sun | C5: 1 | D5: Easy Run | E5: 4.67 | F5: 8.91 | G5: 41.6 | H5: 148 | I5: 529 | J5: Clear 44F | K5: Comfortable effort
A6: 46055 | B6: Mon | C6: 1 | D6: Rest | J6: — | K6: Rest day
A7: 46056 | B7: Tue | C7: 1 | D7: Easy Run | E7: 4.71 | F7: 9.35 | G7: 44 | H7: 145 | I7: 544 | J7: Overcast 46F | K7: Felt smooth
A8: 46057 | B8: Wed | C8: 1 | D8: Tempo | E8: 4.94 | F8: 7.31 | G8: 36.1 | H8: 176 | I8: 572 | J8: Sunny 55F | K8: Lungs on fire
A9: 46058 | B9: Thu | C9: 1 | D9: Easy Run | E9: 4.14 | F9: 9.22 | G9: 38.2 | H9: 152 | I9: 474 | J9: Clear 44F | K9: Easy conversational
A10: 46059 | B10: Fri | C10: 1 | D10: Recovery | E10: 3.11 | F10: 10.15 | G10: 31.6 | H10: 131 | I10: 366 | J10: Light Rain 52F | K10: Easy flush
A11: 46060 | B11: Sat | C11: 1 | D11: Long Run | E11: 7.81 | F11: 9.33 | G11: 72.9 | H11: 156 | I11: 886 | J11: Cloudy 48F | K11: Fueled well
A12: 46061 | B12: Sun | C12: 2 | D12: Easy Run | E12: 4.02 | F12: 9.32 | G12: 37.5 | H12: 148 | I12: 472 | J12: Sunny 55F | K12: Easy conversational
A13: 46062 | B13: Mon | C13: 2 | D13: Rest | J13: — | K13: Active recovery walk
A14: 46063 | B14: Tue | C14: 2 | D14: Easy Run | E14: 4.05 | F14: 9.36 | G14: 37.9 | H14: 145 | I14: 467 | J14: Sunny 60F | K14: Cruise pace
A15: 46064 | B15: Wed | C15: 2 | D15: Tempo | E15: 5.96 | F15: 7.38 | G15: 44 | H15: 171 | I15: 692 | J15: Cloudy 48F | K15: Held pace well
A16: 46065 | B16: Thu | C16: 2 | D16: Easy Run | E16: 4.69 | F16: 9.29 | G16: 43.6 | H16: 145 | I16: 551 | J16: Clear 44F | K16: Felt smooth
A17: 46066 | B17: Fri | C17: 2 | D17: Recovery | E17: 2.86 | F17: 9.98 | G17: 28.5 | H17: 136 | I17: 318 | J17: Windy 50F | K17: Stretched after
A18: 46067 | B18: Sat | C18: 2 | D18: Long Run | E18: 8.85 | F18: 9.38 | G18: 83 | H18: 152 | I18: 1021 | J18: Light Rain 52F | K18: Steady all day
A19: 46068 | B19: Sun | C19: 3 | D19: Easy Run | E19: 4.77 | F19: 8.98 | G19: 42.8 | H19: 150 | I19: 541 | J19: Clear 58F | K19: Comfortable effort
A20: 46069 | B20: Mon | C20: 3 | D20: Rest | J20: — | K20: Full recovery
A21: 46070 | B21: Tue | C21: 3 | D21: Easy Run | E21: 4.91 | F21: 9.29 | G21: 45.6 | H21: 147 | I21: 575 | J21: Sunny 55F | K21: Legs fresh
A22: 46071 | B22: Wed | C22: 3 | D22: Intervals | E22: 4.88 | F22: 7.08 | G22: 34.6 | H22: 179 | I22: 552 | J22: Mist 42F | K22: 10x400 hard
A23: 46072 | B23: Thu | C23: 3 | D23: Easy Run | E23: 4.96 | F23: 9.22 | G23: 45.7 | H23: 146 | I23: 563 | J23: Light Rain 52F | K23: Comfortable effort
A24: 46073 | B24: Fri | C24: 3 | D24: Recovery | E24: 3.29 | F24: 10.02 | G24: 33 | H24: 137 | I24: 391 | J24: Breezy 54F | K24: Easy flush
A25: 46074 | B25: Sat | C25: 3 | D25: Long Run | E25: 10.23 | F25: 9.75 | G25: 99.7 | H25: 153 | I25: 1177 | J25: Mist 42F | K25: Solid long effort
A26: 46075 | B26: Sun | C26: 4 | D26: Easy Run | E26: 4.81 | F26: 9.33 | G26: 44.9 | H26: 146 | I26: 558 | J26: Light Rain 52F | K26: Easy conversational
A27: 46076 | B27: Mon | C27: 4 | D27: Rest | J27: — | K27: Active recovery walk
A28: 46077 | B28: Tue | C28: 4 | D28: Easy Run | E28: 3.98 | F28: 9.09 | G28: 36.2 | H28: 151 | I28: 458 | J28: Sunny 60F | K28: Cruise pace
A29: 46078 | B29: Wed | C29: 4 | D29: Tempo | E29: 5.93 | F29: 7.21 | G29: 42.8 | H29: 169 | I29: 687 | J29: Clear 58F | K29: Last mile tough
A30: 46079 | B30: Thu | C30: 4 | D30: Easy Run | E30: 4.82 | F30: 9.07 | G30: 43.7 | H30: 148 | I30: 552 | J30: Light Rain 52F | K30: Easy conversational
A31: 46080 | B31: Fri | C31: 4 | D31: Recovery | E31: 2.4 | F31: 10.11 | G31: 24.3 | H31: 135 | I31: 277 | J31: Light Rain 52F | K31: Loose legs
A32: 46081 | B32: Sat | C32: 4 | D32: Long Run | E32: 9.2 | F32: 9.69 | G32: 89.1 | H32: 155 | I32: 1069 | J32: Clear 58F | K32: Steady all day
A33: 46082 | B33: Sun | C33: 5 | D33: Easy Run | E33: 4.14 | F33: 9.09 | G33: 37.6 | H33: 146 | I33: 478 | J33: Clear 58F | K33: Felt smooth
A34: 46083 | B34: Mon | C34: 5 | D34: Rest | J34: — | K34: Active recovery walk
A35: 46084 | B35: Tue | C35: 5 | D35: Easy Run | E35: 4.29 | F35: 8.91 | G35: 38.2 | H35: 149 | I35: 506 | J35: Sunny 60F | K35: Comfortable effort
A36: 46085 | B36: Wed | C36: 5 | D36: Hill Run | E36: 4.97 | F36: 8.49 | G36: 42.2 | H36: 167 | I36: 558 | J36: Mist 42F | K36: 6x hill repeats
A37: 46086 | B37: Thu | C37: 5 | D37: Easy Run | E37: 5.07 | F37: 9.17 | G37: 46.5 | H37: 146 | I37: 572 | J37: Mist 42F | K37: Cruise pace
A38: 46087 | B38: Fri | C38: 5 | D38: Recovery | E38: 2.6 | F38: 10.01 | G38: 26 | H38: 137 | I38: 314 | J38: Clear 44F | K38: Loose legs
A39: 46088 | B39: Sat | C39: 5 | D39: Long Run | E39: 13.11 | F39: 9.59 | G39: 125.7 | H39: 155 | I39: 1504 | J39: Windy 50F | K39: Fueled well
A40: 46089 | B40: Sun | C40: 6 | D40: Easy Run | E40: 4.98 | F40: 9.13 | G40: 45.5 | H40: 147 | I40: 564 | J40: Cloudy 48F | K40: Legs fresh
A41: 46090 | B41: Mon | C41: 6 | D41: Rest | J41: — | K41: Rest day
...

Sheet Weekly Summary
A1: Weekly Mileage — Goal vs Actual
A2: Progressive 8-week build · actuals pulled live from Training Log
A4: Week | B4: Goal Miles | C4: Actual Miles | D4: Diff (Act - Goal)
A5: Week 1 | B5: 25 | C5: =SUMIF('Training Log'!C5:C63,1,'Training Log'!E5:E63) -> 29.38 | D5: =C5-B5 -> 4.38
A6: Week 2 | B6: 28 | C6: =SUMIF('Training Log'!C5:C63,2,'Training Log'!E5:E63) -> 30.43 | D6: =C6-B6 -> 2.43
A7: Week 3 | B7: 32 | C7: =SUMIF('Training Log'!C5:C63,3,'Training Log'!E5:E63) -> 33.04 | D7: =C7-B7 -> 1.04
A8: Week 4 | B8: 30 | C8: =SUMIF('Training Log'!C5:C63,4,'Training Log'!E5:E63) -> 31.14 | D8: =C8-B8 -> 1.14
A9: Week 5 | B9: 36 | C9: =SUMIF('Training Log'!C5:C63,5,'Training Log'!E5:E63) -> 34.18 | D9: =C9-B9 -> -1.82
A10: Week 6 | B10: 40 | C10: =SUMIF('Training Log'!C5:C63,6,'Training Log'!E5:E63) -> 36.15 | D10: =C10-B10 -> -3.85
A11: Week 7 | B11: 35 | C11: =SUMIF('Training Log'!C5:C63,7,'Training Log'!E5:E63) -> 33.2 | D11: =C11-B11 -> -1.8
A12: Week 8 | B12: 42 | C12: =SUMIF('Training Log'!C5:C63,8,'Training Log'!E5:E63) -> 38.02 | D12: =C12-B12 -> -3.98
A13: Week 9 | B13: 20 | C13: =SUMIF('Training Log'!C5:C63,9,'Training Log'!E5:E63) -> 8.98 | D13: =C13-B13 -> -11.02
A14: TOTAL | B14: =SUM(B5:B13) -> 288 | C14: =SUM(C5:C13) -> 274.52 | D14: =C14-B14 -> -13.48
